#VRML_SIM R2022a utf8
WorldInfo {
}
Viewpoint {
  orientation -0.5773502691896258 0.5773502691896258 0.5773502691896258 2.0944
  position -0.05000261886777647 -0.060002618875176966 4.052252973352447
}
TexturedBackground {
}
TexturedBackgroundLight {
}
RectangleArena {
  floorSize 2 2
}
Robot {
  translation 0 0 0.025
  children [
    HingeJoint {
      jointParameters HingeJointParameters {
        axis 0 1 0
        anchor -0.05 -0.06 0
      }
      device [
        RotationalMotor {
          name "wheel4"
        }
      ]
      endPoint Solid {
        translation -0.050000000000000024 -0.060000000000000026 0
        rotation 1 -2.994708204376036e-22 0 1.5708
        children [
          DEF wheel Shape {
            appearance Appearance {
              material Material {
                diffuseColor 0.666667 0 0
              }
            }
            geometry Cylinder {
              height 0.02
              radius 0.04
            }
          }
        ]
        name "wheel4"
        boundingObject USE wheel
        physics Physics {
        }
      }
    }
    HingeJoint {
      jointParameters HingeJointParameters {
        axis 0 1 0
        anchor -0.05 0.06 0
      }
      device [
        RotationalMotor {
          name "wheel3"
        }
      ]
      endPoint Solid {
        translation -0.050000000000000024 0.060000000000000026 0
        rotation 1 0 -2.994708204376036e-22 1.5708
        children [
          DEF wheel Shape {
            appearance Appearance {
              material Material {
                diffuseColor 0.666667 0 0
              }
            }
            geometry Cylinder {
              height 0.02
              radius 0.04
            }
          }
        ]
        name "wheel3"
        boundingObject USE wheel
        physics Physics {
        }
      }
    }
    HingeJoint {
      jointParameters HingeJointParameters {
        axis 0 1 0
        anchor 0.05 -0.06 0
      }
      device [
        RotationalMotor {
          name "wheel2"
        }
      ]
      endPoint Solid {
        translation 0.050000000000000024 -0.060000000000000026 -7.119062821282043e-19
        rotation 1 1.9626119688198792e-17 3.9252239376397585e-17 1.5707999999999998
        children [
          DEF WHEEL Shape {
            appearance Appearance {
              material Material {
                diffuseColor 0.666667 0 0
              }
            }
            geometry Cylinder {
              height 0.02
              radius 0.04
            }
          }
        ]
        name "wheel2"
        boundingObject USE WHEEL
        physics Physics {
        }
      }
    }
    HingeJoint {
      jointParameters HingeJointParameters {
        axis 0 1 0
        anchor 0.05 0.06 0
      }
      device [
        RotationalMotor {
          name "wheel1"
        }
      ]
      endPoint DEF WHEEL1 Solid {
        translation 0.050000000000000024 0.060000000000000026 0
        rotation 1 2.994708204376036e-22 0 1.5708
        children [
          DEF WHEEL Shape {
            appearance Appearance {
              material Material {
                diffuseColor 0.666667 0 0
              }
            }
            geometry Cylinder {
              height 0.02
              radius 0.04
            }
          }
        ]
        boundingObject USE WHEEL
        physics DEF WHEEL_PH Physics {
        }
      }
    }
    DEF BODY Shape {
      appearance Appearance {
        material Material {
          diffuseColor 0 1 0
        }
      }
      geometry Box {
        size 0.2 0.1 0.05
      }
    }
  ]
  name "4_wheel_car"
  boundingObject USE BODY
  physics Physics {
  }
  controller "key_board_controller"
}
